Traceback (most recent call last):
  File "C:\Users\Owner\anaconda3\lib\site-packages\jupyter_cache\executors\utils.py", line 58, in single_nb_execution
    executenb(
  File "C:\Users\Owner\anaconda3\lib\site-packages\nbclient\client.py", line 1204, in execute
    return NotebookClient(nb=nb, resources=resources, km=km, **kwargs).execute()
  File "C:\Users\Owner\anaconda3\lib\site-packages\nbclient\util.py", line 84, in wrapped
    return just_run(coro(*args, **kwargs))
  File "C:\Users\Owner\anaconda3\lib\site-packages\nbclient\util.py", line 62, in just_run
    return loop.run_until_complete(coro)
  File "C:\Users\Owner\anaconda3\lib\asyncio\base_events.py", line 647, in run_until_complete
    return future.result()
  File "C:\Users\Owner\anaconda3\lib\site-packages\nbclient\client.py", line 663, in async_execute
    await self.async_execute_cell(
  File "C:\Users\Owner\anaconda3\lib\site-packages\nbclient\client.py", line 965, in async_execute_cell
    await self._check_raise_for_error(cell, cell_index, exec_reply)
  File "C:\Users\Owner\anaconda3\lib\site-packages\nbclient\client.py", line 862, in _check_raise_for_error
    raise CellExecutionError.from_cell_and_msg(cell, exec_reply_content)
nbclient.exceptions.CellExecutionError: An error occurred while executing the following cell:
------------------
%load_ext autoreload
%autoreload 2

import numpy as np
import sys
from Utilities.models_2_0 import *
from Utilities.plots_2_0 import *
from IPython.display import Markdown, display

excel_filename = 'Tungsten/Tungsten.xlsx'
material_name = "Tungsten"
sys.path.append('/path/to/Utilities')

RT = 273
f_size = 10
legend_size = 6
m_size = 35
------------------

[1;31m---------------------------------------------------------------------------[0m
[1;31mModuleNotFoundError[0m                       Traceback (most recent call last)
[1;32m~\AppData\Local\Temp\ipykernel_50492\2717921014.py[0m in [0;36m<module>[1;34m[0m
[0;32m      4[0m [1;32mimport[0m [0mnumpy[0m [1;32mas[0m [0mnp[0m[1;33m[0m[1;33m[0m[0m
[0;32m      5[0m [1;32mimport[0m [0msys[0m[1;33m[0m[1;33m[0m[0m
[1;32m----> 6[1;33m [1;32mfrom[0m [0mUtilities[0m[1;33m.[0m[0mmodels_2_0[0m [1;32mimport[0m [1;33m*[0m[1;33m[0m[1;33m[0m[0m
[0m[0;32m      7[0m [1;32mfrom[0m [0mUtilities[0m[1;33m.[0m[0mplots_2_0[0m [1;32mimport[0m [1;33m*[0m[1;33m[0m[1;33m[0m[0m
[0;32m      8[0m [1;32mfrom[0m [0mIPython[0m[1;33m.[0m[0mdisplay[0m [1;32mimport[0m [0mMarkdown[0m[1;33m,[0m [0mdisplay[0m[1;33m[0m[1;33m[0m[0m

[1;31mModuleNotFoundError[0m: No module named 'Utilities'
ModuleNotFoundError: No module named 'Utilities'

